Workbook

Sheet Guía de Uso
A1: AGROMACK | B1: Kit Avícola Profesional — Sistema de Gestión y Costeo
A3: CALCULADORA INTEGRAL AVÍCOLA
A4: Planifica, costea y proyecta tu producción avícola en minutos — postura, cría y venta, o ciclo completo.
A6: 📂 ¿QUÉ INCLUYE ESTE KIT?
A7: Datos Técnicos | B7: Parámetros de referencia por línea genética (Hy-Line, Lohmann): curvas de postura, consumo de alimento y mortalidad. Alimenta automáticamente los 3 módulos de cálculo.
A8: Postura | B8: Compra de gallinas listas para poner. Calcula inversión, dimensionamiento e ingresos hasta la pelecha (24 meses).
A9: Cría y Venta | B9: Compra de pollitas de 1 día para vender como pollonas listas para postura. Ideal para negocios de recría.
A10: Ciclo Completo | B10: Cría desde pollita de 1 día hasta el final de la etapa de postura. Vista integral del negocio completo.
A11: Dashboard | B11: Resumen ejecutivo con los KPI clave de los 3 modos de operación y gráfico comparativo, actualizado en tiempo real.
A13: ⚙️ CÓMO USAR ESTA CALCULADORA
A14: Paso 1 | B14: Ve a la hoja "Datos Técnicos" y confirma o ajusta los parámetros técnicos de tu línea genética (opcional, ya vienen precargados).
A15: Paso 2 | B15: Elige el módulo que se ajusta a tu negocio: "Postura", "Cría y Venta" o "Ciclo Completo".
A16: Paso 3 | B16: Ingresa tus datos en las celdas AZULES (número de aves, precios, costos). El resto se calcula solo.
A17: Paso 4 | B17: Revisa el flujo mensual proyectado: verde = flujo acumulado positivo, rojo = aún en déficit.
A18: Paso 5 | B18: Ve al "Dashboard" para comparar los 3 modos y decidir cuál conviene más a tu proyecto.
A20: 🎨 CÓDIGO DE COLORES
A21: Celda azul | B21: Dato editable: aquí ingresas tus propios números (precios, cantidades, costos).
A22: Celda verde clara | B22: Cálculo técnico automático (consumo, área, equipos). No requiere edición.
A23: Fila verde | B23: Flujo de caja acumulado positivo: el proyecto ya recuperó la inversión.
A24: Fila roja | B24: Flujo de caja acumulado negativo: el proyecto aún no recupera la inversión.
A26: 💡 RECOMENDACIONES
A27: • | B27: Usa precios y costos actualizados de tu zona para proyecciones realistas.
A28: • | B28: Las curvas Lohmann son aproximaciones conservadoras (ver hoja Datos Técnicos).
A29: • | B29: Este kit es una herramienta de apoyo a la decisión; valida los resultados con tu propia experiencia de campo.
A31: AGROMACK | B31: www.agromack.cl · contacto@agromack.cl · Versión 1.0

Sheet Dashboard
A1: AGROMACK | C1: Kit Avícola Profesional
A3: DASHBOARD COMPARATIVO — 3 MODOS DE OPERACIÓN
A4: Resumen ejecutivo enlazado a los módulos de cálculo. Se actualiza automáticamente al cambiar los supuestos en cada hoja.
A6: Indicador | B6: Postura | C6: Cría y Venta | D6: Ciclo Completo
A7: Inversión inicial ($) | B7: =Postura!B37 -> 9631.6 | C7: ='Cría y Venta'!B26 -> 3500 | D7: ='Ciclo Completo'!B35 -> 6981.6
A8: Ingreso total proyectado ($) | B8: =SUM(Postura!E43:E66) -> 28888.346 | C8: ='Cría y Venta'!B40 -> 3088.169 | D8: =SUM('Ciclo Completo'!F45:F68) -> 27449.875
A9: Costo operativo total ($) | B9: =SUM(Postura!J43:J66) -> 19812.966 | C9: =SUM('Cría y Venta'!E31:F36) -> 1618.1009 | D9: =SUM('Ciclo Completo'!G41:G68) -> 20294.84
A10: Flujo acumulado final ($) | B10: =Postura!L66 -> -556.2205 | C10: ='Cría y Venta'!I36 -> -2029.9319 | D10: ='Ciclo Completo'!I68 -> 173.43506
A11: Margen sobre inversión (%) | B11: =B10/B7 -> -0.057749544 | C11: =C10/C7 -> -0.57998055 | D11: =D10/D7 -> 0.024841736
A12: Periodo de recuperación | B12: {=IFERROR("Mes "&INDEX(Postura!A43:A66,MATCH(TRUE,Postura!L43:L66>=0,0)),"Fuera del periodo")} -> Mes 19 | C12: {=IFERROR("Sem "&INDEX('Cría y Venta'!B31:B36,MATCH(TRUE,'Cría y Venta'!I31:I36>=0,0)),"Fuera del periodo")} -> Fuera del periodo | D12: {=IFERROR("Mes "&INDEX('Ciclo Completo'!A41:A68,MATCH(TRUE,'Ciclo Completo'!I41:I68>=0,0)),"Fuera del periodo")} -> Mes 19

Sheet Postura
A1: AGROMACK | G1: Kit Avícola Profesional · Sistema de Gestión y Costeo
A2: CALCULADORA AVÍCOLA — MODO POSTURA
A3: Compra de gallinas listas para poner → operar hasta la pelecha
A5: DATOS DEL PROYECTO | D5: LÍNEA GENÉTICA (ingresa 1, 2, 3 o 4)
A6: Número de aves | B6: 500 | D6: 1=Hy-Line Brown · 2=Lohmann Brown · 3=Hy-Line W-36 · 4=Lohmann LSL
A7: Precio gallina lista / unidad | B7: 6.5 | D7: Línea seleccionada | E7: 1
A8: Precio venta huevo / unidad | B8: 0.12 | D8: Sistema (1=Piso, 2=Jaula, 3=Semi-pastoreo) | E8: 1
A9: Precio alimento postura / kg | B9: 0.5 | D9: Comedero (1=Tolva, 2=Lineal) | E9: 1
A10: Costo construcción / m² | B10: 80 | D10: Bebedero (1=Nipple, 2=Campana, 3=Canal) | E10: 1
A11: Infraestructura adicional (monto fijo) | B11: 500 | D11: Precio unitario comedero | E11: 18
A12: Vida útil infraestructura (meses) | B12: 120 | D12: Precio unitario bebedero | E12: 1.2
A13: Mano de obra mensual | B13: 0 | D13: Precio unitario nido | E13: 15
A14: Otros costos mensuales | B14: 0
A15: Reposición aves (%/mes) | B15: 0
A16: Meses a proyectar | B16: 24
A17: Ingresa tus valores en las celdas azules
A19: DIMENSIONAMIENTO TÉCNICO
A20: Consumo alimento g/ave/día | B20: =INDEX('Datos Técnicos'!D12:D15,E7) -> 115
A21: Ratio agua:alimento | B21: =INDEX('Datos Técnicos'!E12:E15,E7) -> 1.8
A22: m²/ave según sistema | B22: =IF(E8=1,INDEX('Datos Técnicos'!F12:F15,E7),IF(E8=2,INDEX('Datos Técnicos'!G12:G15,E7),INDEX('Datos Técnicos'!H12:H15,E7))) -> 0.1
A23: Área requerida (m²) | B23: =B6*B22 -> 50
A24: Alimento diario (kg) | B24: =B6*B20/1000 -> 57.5
A25: Alimento mensual (kg) | B25: =B24*'Datos Técnicos'!B5 -> 1748
A26: Agua diaria (L) | B26: =B24*B21 -> 103.5
A27: Comederos requeridos | B27: =IF(E9=1,CEILING(B6/INDEX('Datos Técnicos'!K12:K15,E7),1),CEILING(B6*INDEX('Datos Técnicos'!J12:J15,E7)/100,1)) -> 17
A28: Bebederos requeridos | B28: =IF(E10=1,CEILING(B6/INDEX('Datos Técnicos'!L12:L15,E7),1),IF(E10=2,CEILING(B6/INDEX('Datos Técnicos'!M12:M15,E7),1),CEILING(B6*INDEX('Datos Técnicos'!N12:N15,E7)/100,1))) -> 63
A29: Nidos requeridos | B29: =CEILING(B6/INDEX('Datos Técnicos'!O12:O15,E7),1) -> 100
A31: INVERSIÓN INICIAL
A32: Costo aves | B32: =B6*B7 -> 3250
A33: Costo infraestructura | B33: =B23*B10+B11 -> 4500
A34: Costo comederos | B34: =B27*E11 -> 306
A35: Costo bebederos | B35: =B28*E12 -> 75.6
A36: Costo nidos | B36: =B29*E13 -> 1500
A37: TOTAL INVERSIÓN INICIAL | B37: =SUM(B32:B36) -> 9631.6
A38: Depreciación mensual infra | B38: =B33/B12 -> 37.5
A40: FLUJO MENSUAL PROYECTADO
A41: La inversión se descuenta del flujo acumulado desde el mes 1. Mortalidad 0.5%/mes.
A42: Mes | B42: Aves productivas | C42: Postura % | D42: Huevos | E42: Ingresos | F42: Alimento kg | G42: Costo alim. | H42: Otros costos | I42: Reposición | J42: Egresos op. | K42: Flujo neto | L42: Flujo acumulado
A43: 1 | B43: =B6 -> 500 | C43: =INDEX('Datos Técnicos'!B20:Y23,E7,1)/100 -> 0.62 | D43: =B43*C43*'Datos Técnicos'!B5 -> 9424 | E43: =D43*B8 -> 1130.88 | F43: =B43*B20/1000*'Datos Técnicos'!B5 -> 1748 | G43: =F43*B9 -> 874 | H43: =B13+B14 -> 0 | I43: 0 | J43: =G43+H43+I43 -> 874 | K43: =E43-J43 -> 256.88 | L43: =-B37+K43 -> -9374.72
A44: 2 | B44: =B6*(1-'Datos Técnicos'!B6)^1 -> 497.5 | C44: =INDEX('Datos Técnicos'!B20:Y23,E7,2)/100 -> 0.92 | D44: =B44*C44*'Datos Técnicos'!B5 -> 13914.08 | E44: =D44*B8 -> 1669.6896 | F44: =B44*B20/1000*'Datos Técnicos'!B5 -> 1739.26 | G44: =F44*B9 -> 869.63 | H44: =B13+B14 -> 0 | I44: =IF(B15>0,B6*B15*B7,0) -> 0 | J44: =G44+H44+I44 -> 869.63 | K44: =E44-J44 -> 800.0596 | L44: =L43+K44 -> -8574.6604
...

Sheet Cría y Venta
A1: AGROMACK | F1: Kit Avícola Profesional · Sistema de Gestión y Costeo
A2: CALCULADORA AVÍCOLA — MODO CRÍA Y VENTA
A3: Compra de pollitas de 1 día → venta como pollonas listas para postura
A5: DATOS DEL PROYECTO | D5: LÍNEA GENÉTICA (1, 2, 3 o 4)
A6: Número de pollitas | B6: 500 | D6: 1=Hy-Line Brown · 2=Lohmann Brown · 3=Hy-Line W-36 · 4=Lohmann LSL
A7: Precio pollita 1 día | B7: 1.2 | D7: Línea seleccionada | E7: 1
A8: Precio venta pollona | B8: 6.5
A9: Precio alimento recría / kg | B9: 0.45
A10: Costo construcción / m² | B10: 80
A11: Infraestructura adicional | B11: 500
A12: Vida útil infraestructura (meses) | B12: 120
A13: Mano de obra mensual | B13: 0
A14: Otros costos mensuales | B14: 0
A15: Semana de venta | B15: 17
A19: CÁLCULOS DEL CICLO DE CRÍA
A20: Área cría (m²) | B20: =B6*INDEX('Datos Técnicos'!I12:I15,E7) -> 30
A21: Mortalidad acum. recría (%) | B21: =1-(1-'Datos Técnicos'!B7)^B15 -> 0.049794169
A22: Aves estimadas al vender | B22: =B6*(1-B21) -> 475.10292
A23: Ingreso por venta | B23: =B22*B8 -> 3088.169
A24: Costo pollitas | B24: =B6*B7 -> 600
A25: Costo infraestructura | B25: =B20*B10+B11 -> 2900
A26: TOTAL INVERSIÓN INICIAL | B26: =B24+B25 -> 3500
A28: FLUJO MENSUAL PROYECTADO
A29: Alimento de recría por mes. El ingreso por venta se registra en el último mes.
A30: Mes | B30: Semanas | C30: Aves vivas | D30: Alimento kg (est.) | E30: Costo alimento | F30: Otros costos | G30: Ingreso venta | H30: Flujo neto | I30: Flujo acumulado
A31: 1 | B31: =IF(1>B15,"-",1&"–"&MIN(4,B15)) -> 1–4 | C31: =IF(1>B15,0,B6*(1-'Datos Técnicos'!B7)^MIN(4,B15)) -> 494.02695 | D31: =IF(1>B15,0,C31*AVERAGE(INDEX('Datos Técnicos'!B28:R29,IF(E7<=2,1,2),1):INDEX('Datos Técnicos'!B28:R29,IF(E7<=2,1,2),MIN(4,17)))*7*MIN(4,B15-1+1)/1000) -> 318.15335 | E31: =D31*B9 -> 143.16901 | F31: =IF(1>B15,0,B13+B14) -> 0 | G31: =IF(AND(1<=B15,MIN(4,B15)>=B15),C31*B8,0) -> 0 | H31: =G31-E31-F31 -> -143.16901 | I31: =-B26+H31 -> -3643.169
A32: 2 | B32: =IF(5>B15,"-",5&"–"&MIN(8,B15)) -> 5–8 | C32: =IF(5>B15,0,B6*(1-'Datos Técnicos'!B7)^MIN(8,B15)) -> 488.12525 | D32: =IF(5>B15,0,C32*AVERAGE(INDEX('Datos Técnicos'!B28:R29,IF(E7<=2,1,2),5):INDEX('Datos Técnicos'!B28:R29,IF(E7<=2,1,2),MIN(8,17)))*7*MIN(4,B15-5+1)/1000) -> 744.87913 | E32: =D32*B9 -> 335.19561 | F32: =IF(5>B15,0,B13+B14) -> 0 | G32: =IF(AND(5<=B15,MIN(8,B15)>=B15),C32*B8,0) -> 0 | H32: =G32-E32-F32 -> -335.19561 | I32: =I31+H32 -> -3978.3646
A33: 3 | B33: =IF(9>B15,"-",9&"–"&MIN(12,B15)) -> 9–12 | C33: =IF(9>B15,0,B6*(1-'Datos Técnicos'!B7)^MIN(12,B15)) -> 482.29405 | D33: =IF(9>B15,0,C33*AVERAGE(INDEX('Datos Técnicos'!B28:R29,IF(E7<=2,1,2),9):INDEX('Datos Técnicos'!B28:R29,IF(E7<=2,1,2),MIN(12,17)))*7*MIN(4,B15-9+1)/1000) -> 999.31327 | E33: =D33*B9 -> 449.69097 | F33: =IF(9>B15,0,B13+B14) -> 0 | G33: =IF(AND(9<=B15,MIN(12,B15)>=B15),C33*B8,0) -> 0 | H33: =G33-E33-F33 -> -449.69097 | I33: =I32+H33 -> -4428.0556
A34: 4 | B34: =IF(13>B15,"-",13&"–"&MIN(16,B15)) -> 13–16 | C34: =IF(13>B15,0,B6*(1-'Datos Técnicos'!B7)^MIN(16,B15)) -> 476.53251 | D34: =IF(13>B15,0,C34*AVERAGE(INDEX('Datos Técnicos'!B28:R29,IF(E7<=2,1,2),13):INDEX('Datos Técnicos'!B28:R29,IF(E7<=2,1,2),MIN(16,17)))*7*MIN(4,B15-13+1)/1000) -> 1200.8619 | E34: =D34*B9 -> 540.38787 | F34: =IF(13>B15,0,B13+B14) -> 0 | G34: =IF(AND(13<=B15,MIN(16,B15)>=B15),C34*B8,0) -> 0 | H34: =G34-E34-F34 -> -540.38787 | I34: =I33+H34 -> -4968.4435
A35: 5 | B35: =IF(17>B15,"-",17&"–"&MIN(20,B15)) -> 17–17 | C35: =IF(17>B15,0,B6*(1-'Datos Técnicos'!B7)^MIN(20,B15)) -> 475.10292 | D35: =IF(17>B15,0,C35*AVERAGE(INDEX('Datos Técnicos'!B28:R29,IF(E7<=2,1,2),17):INDEX('Datos Técnicos'!B28:R29,IF(E7<=2,1,2),MIN(20,17)))*7*MIN(4,B15-17+1)/1000) -> 332.57204 | E35: =D35*B9 -> 149.65742 | F35: =IF(17>B15,0,B13+B14) -> 0 | G35: =IF(AND(17<=B15,MIN(20,B15)>=B15),C35*B8,0) -> 3088.169 | H35: =G35-E35-F35 -> 2938.5115 | I35: =I34+H35 -> -2029.9319
A36: 6 | B36: =IF(21>B15,"-",21&"–"&MIN(24,B15)) -> - | C36: =IF(21>B15,0,B6*(1-'Datos Técnicos'!B7)^MIN(24,B15)) -> 0 | D36: 0 | E36: =D36*B9 -> 0 | F36: =IF(21>B15,0,B13+B14) -> 0 | G36: =IF(AND(21<=B15,MIN(24,B15)>=B15),C36*B8,0) -> 0 | H36: =G36-E36-F36 -> 0 | I36: =I35+H36 -> -2029.9319
A38: RESUMEN ECONÓMICO
A39: Inversión inicial | B39: =B26 -> 3500
A40: Ingreso total por venta | B40: =B23 -> 3088.169
A41: Margen bruto estimado | B41: =B40-B24-SUM(E31:E36)-SUM(F31:F36) -> 870.06808

Sheet Ciclo Completo
A1: AGROMACK | F1: Kit Avícola Profesional · Sistema de Gestión y Costeo
A2: CALCULADORA AVÍCOLA — CICLO COMPLETO
A3: Cría desde pollita de 1 día → postura hasta la pelecha
A5: DATOS DEL PROYECTO | D5: LÍNEA GENÉTICA (1, 2, 3 o 4)
A6: Número de pollitas | B6: 500 | D6: 1=Hy-Line Brown · 2=Lohmann Brown · 3=Hy-Line W-36 · 4=Lohmann LSL
A7: Precio pollita 1 día | B7: 1.2 | D7: Línea seleccionada | E7: 1
A8: Precio venta huevo / unidad | B8: 0.12 | D8: Sistema (1=Piso, 2=Jaula, 3=Semi-pastoreo) | E8: 1
A9: Precio alimento recría / kg | B9: 0.45 | D9: Comedero (1=Tolva, 2=Lineal) | E9: 1
A10: Precio alimento postura / kg | B10: 0.5 | D10: Bebedero (1=Nipple, 2=Campana, 3=Canal) | E10: 1
A11: Costo construcción / m² | B11: 80 | D11: Precio unitario comedero | E11: 18
A12: Infraestructura adicional | B12: 500 | D12: Precio unitario bebedero | E12: 1.2
A13: Vida útil infraestructura (meses) | B13: 120 | D13: Precio unitario nido | E13: 15
A14: Mano de obra mensual | B14: 0
A15: Otros costos mensuales | B15: 0
A16: Reposición aves postura (%/mes) | B16: 0
A19: DIMENSIONAMIENTO Y COSTOS
A20: Consumo postura g/ave/día | B20: =INDEX('Datos Técnicos'!D12:D15,E7) -> 115
A21: m²/ave postura | B21: =IF(E8=1,INDEX('Datos Técnicos'!F12:F15,E7),IF(E8=2,INDEX('Datos Técnicos'!G12:G15,E7),INDEX('Datos Técnicos'!H12:H15,E7))) -> 0.1
A22: Área requerida (m²) | B22: =B6*B21 -> 50
A23: Comederos requeridos | B23: =IF(E9=1,CEILING(B6/INDEX('Datos Técnicos'!K12:K15,E7),1),CEILING(B6*INDEX('Datos Técnicos'!J12:J15,E7)/100,1)) -> 17
A24: Bebederos requeridos | B24: =IF(E10=1,CEILING(B6/INDEX('Datos Técnicos'!L12:L15,E7),1),IF(E10=2,CEILING(B6/INDEX('Datos Técnicos'!M12:M15,E7),1),CEILING(B6*INDEX('Datos Técnicos'!N12:N15,E7)/100,1))) -> 63
A25: Nidos requeridos | B25: =CEILING(B6/INDEX('Datos Técnicos'!O12:O15,E7),1) -> 100
A26: Mortalidad acum. recría (%) | B26: =1-(1-'Datos Técnicos'!B7)^17 -> 0.049794169
A27: Aves al inicio postura | B27: =B6*(1-B26) -> 475.10292
A29: INVERSIÓN INICIAL
A30: Costo pollitas | B30: =B6*B7 -> 600
A31: Costo infraestructura | B31: =B22*B11+B12 -> 4500
A32: Costo comederos | B32: =B23*E11 -> 306
A33: Costo bebederos | B33: =B24*E12 -> 75.6
A34: Costo nidos | B34: =B25*E13 -> 1500
A35: TOTAL INVERSIÓN INICIAL | B35: =SUM(B30:B34) -> 6981.6
A36: Depreciación mensual infra | B36: =B31/B13 -> 37.5
A38: FLUJO MENSUAL PROYECTADO
A39: Fase ámbar = recría (sin ingresos). Fase verde = postura.
A40: Mes | B40: Fase | C40: Aves | D40: Postura/Sem. | E40: Huevos / Alim. kg | F40: Ingresos | G40: Egresos op. | H40: Flujo neto | I40: Flujo acumulado
A41: 1 | B41: Recría | C41: =B6*(1-'Datos Técnicos'!B7)^4 -> 494.02695 | D41: Sem. 1–4 | E41: =C41*AVERAGE(INDEX('Datos Técnicos'!B28:R29,IF(E7<=2,1,2),1):INDEX('Datos Técnicos'!B28:R29,IF(E7<=2,1,2),4))*7*4/1000 -> 318.15335 | F41: — | G41: =E41*B9+B14+B15 -> 143.16901 | H41: =-G41 -> -143.16901 | I41: =-B35+H41 -> -7124.769
A42: 2 | B42: Recría | C42: =B6*(1-'Datos Técnicos'!B7)^8 -> 488.12525 | D42: Sem. 5–8 | E42: =C42*AVERAGE(INDEX('Datos Técnicos'!B28:R29,IF(E7<=2,1,2),5):INDEX('Datos Técnicos'!B28:R29,IF(E7<=2,1,2),8))*7*4/1000 -> 744.87913 | F42: — | G42: =E42*B9+B14+B15 -> 335.19561 | H42: =-G42 -> -335.19561 | I42: =I41+H42 -> -7459.9646
A43: 3 | B43: Recría | C43: =B6*(1-'Datos Técnicos'!B7)^12 -> 482.29405 | D43: Sem. 9–12 | E43: =C43*AVERAGE(INDEX('Datos Técnicos'!B28:R29,IF(E7<=2,1,2),9):INDEX('Datos Técnicos'!B28:R29,IF(E7<=2,1,2),12))*7*4/1000 -> 999.31327 | F43: — | G43: =E43*B9+B14+B15 -> 449.69097 | H43: =-G43 -> -449.69097 | I43: =I42+H43 -> -7909.6556
A44: 4 | B44: Recría | C44: =B6*(1-'Datos Técnicos'!B7)^16 -> 476.53251 | D44: Sem. 13–16 | E44: =C44*AVERAGE(INDEX('Datos Técnicos'!B28:R29,IF(E7<=2,1,2),13):INDEX('Datos Técnicos'!B28:R29,IF(E7<=2,1,2),16))*7*4/1000 -> 1200.8619 | F44: — | G44: =E44*B9+B14+B15 -> 540.38787 | H44: =-G44 -> -540.38787 | I44: =I43+H44 -> -8450.0435
A45: 5 | B45: Postura | C45: =B27 -> 475.10292 | D45: =INDEX('Datos Técnicos'!B20:Y23,E7,1)/100 -> 0.62 | E45: =C45*D45*'Datos Técnicos'!B5 -> 8954.7398 | F45: =E45*B8 -> 1074.5688 | G45: =C45*B20/1000*'Datos Técnicos'!B5*B10+B14+B15+IF(B16>0,B6*B16*B7,0) -> 830.4799 | H45: =F45-G45 -> 244.08887 | I45: =I44+H45 -> -8205.9546
...

Sheet Datos Técnicos
A1: AGROMACK | N1: Kit Avícola Profesional · Sistema de Gestión y Costeo
A2: DATOS TÉCNICOS Y CURVAS DE REFERENCIA
A4: Constantes
A5: Días promedio por mes | B5: 30.4
A6: Mortalidad mensual postura (%) | B6: 0.005
A7: Mortalidad semanal recría (%) | B7: 0.003
A8: Semanas de recría estándar | B8: 17
A10: Parámetros por línea genética
A11: Línea | B11: Tipo | C11: Aprox. | D11: Consumo g/día | E11: Agua ratio | F11: m²/ave piso | G11: m²/ave jaula | H11: m²/ave semi | I11: m²/ave cría | J11: Comedero cm | K11: Aves/tolva | L11: Aves/nipple | M11: Aves/campana | N11: Bebedero cm | O11: Aves/nido | P11: Postura prom % | Q11: Postura pico % | R11: Sem. pelecha
A12: Hy-Line Brown | B12: Café | C12: No | D12: 115 | E12: 1.8 | F12: 0.1 | G12: 0.055 | H12: 0.25 | I12: 0.06 | J12: 10 | K12: 30 | L12: 8 | M12: 80 | N12: 10 | O12: 5 | P12: 92 | Q12: 96 | R12: 72
A13: Lohmann Brown | B13: Café | C13: Sí | D13: 115 | E13: 1.8 | F13: 0.1 | G13: 0.055 | H13: 0.25 | I13: 0.06 | J13: 10 | K13: 30 | L13: 8 | M13: 80 | N13: 10 | O13: 5 | P13: 92 | Q13: 96 | R13: 72
A14: Hy-Line W-36 | B14: Blanco | C14: No | D14: 100 | E14: 1.8 | F14: 0.09 | G14: 0.045 | H14: 0.22 | I14: 0.055 | J14: 10 | K14: 30 | L14: 8 | M14: 80 | N14: 10 | O14: 5 | P14: 93 | Q14: 97 | R14: 74
A15: Lohmann LSL | B15: Blanco | C15: Sí | D15: 100 | E15: 1.8 | F15: 0.09 | G15: 0.045 | H15: 0.22 | I15: 0.055 | J15: 10 | K15: 30 | L15: 8 | M15: 80 | N15: 10 | O15: 5 | P15: 93 | Q15: 97 | R15: 74
A18: Curvas de postura mensual (%)
A19: Línea | B19: Mes 1 | C19: Mes 2 | D19: Mes 3 | E19: Mes 4 | F19: Mes 5 | G19: Mes 6 | H19: Mes 7 | I19: Mes 8 | J19: Mes 9 | K19: Mes 10 | L19: Mes 11 | M19: Mes 12 | N19: Mes 13 | O19: Mes 14 | P19: Mes 15 | Q19: Mes 16 | R19: Mes 17 | S19: Mes 18 | T19: Mes 19 | U19: Mes 20 | V19: Mes 21 | W19: Mes 22 | X19: Mes 23 | Y19: Mes 24
A20: Hy-Line Brown | B20: 62 | C20: 92 | D20: 95 | E20: 95 | F20: 94 | G20: 93 | H20: 91 | I20: 89 | J20: 86 | K20: 83 | L20: 79 | M20: 74 | N20: 71 | O20: 68 | P20: 64 | Q20: 60 | R20: 57 | S20: 54 | T20: 50 | U20: 47 | V20: 44 | W20: 41 | X20: 38 | Y20: 35
A21: Lohmann Brown | B21: 60 | C21: 91 | D21: 94 | E21: 95 | F21: 94 | G21: 92 | H21: 90 | I21: 88 | J21: 85 | K21: 82 | L21: 78 | M21: 74 | N21: 70 | O21: 67 | P21: 63 | Q21: 59 | R21: 56 | S21: 53 | T21: 50 | U21: 47 | V21: 44 | W21: 41 | X21: 38 | Y21: 35
A22: Hy-Line W-36 | B22: 64 | C22: 93 | D22: 96 | E22: 96 | F22: 95 | G22: 94 | H22: 92 | I22: 90 | J22: 87 | K22: 84 | L22: 80 | M22: 76 | N22: 73 | O22: 69 | P22: 66 | Q22: 62 | R22: 58 | S22: 55 | T22: 52 | U22: 49 | V22: 46 | W22: 43 | X22: 40 | Y22: 37
A23: Lohmann LSL | B23: 63 | C23: 92 | D23: 96 | E23: 96 | F23: 95 | G23: 93 | H23: 91 | I23: 89 | J23: 86 | K23: 83 | L23: 79 | M23: 75 | N23: 72 | O23: 68 | P23: 65 | Q23: 61 | R23: 58 | S23: 54 | T23: 51 | U23: 48 | V23: 45 | W23: 42 | X23: 39 | Y23: 36
A26: Consumo recría g/ave/día por semana
A27: Tipo | B27: Sem 1 | C27: Sem 2 | D27: Sem 3 | E27: Sem 4 | F27: Sem 5 | G27: Sem 6 | H27: Sem 7 | I27: Sem 8 | J27: Sem 9 | K27: Sem 10 | L27: Sem 11 | M27: Sem 12 | N27: Sem 13 | O27: Sem 14 | P27: Sem 15 | Q27: Sem 16 | R27: Sem 17
A28: Café (Hy-Line Brown / Lohmann Brown) | B28: 10 | C28: 18 | D28: 28 | E28: 36 | F28: 44 | G28: 52 | H28: 58 | I28: 64 | J28: 68 | K28: 72 | L28: 76 | M28: 80 | N28: 84 | O28: 88 | P28: 92 | Q28: 96 | R28: 100
A29: Blanco (Hy-Line W-36 / Lohmann LSL) | B29: 10 | C29: 17 | D29: 26 | E29: 34 | F29: 42 | G29: 49 | H29: 55 | I29: 60 | J29: 64 | K29: 68 | L29: 72 | M29: 75 | N29: 78 | O29: 81 | P29: 84 | Q29: 87 | R29: 90
A31: Las curvas Lohmann son aproximaciones conservadoras, no datos oficiales del fabricante.
